PyGaze crashes in OpenSesame during EyeTribe calibration 

Hello,

We are encountering an error on the OpenSesame EyeTribe template, during the calibration phase. The first calibration point is presented for about 1500ms, and then the experiment exits with a KeyError exception.

```
Unexpected error

item-stack: experiment[run].pygaze_init[run]
exception message: 'values'
time: Wed Jun 22 14:08:56 2016
exception type: KeyError

Traceback:
  File "dist\libqtopensesame\misc\process.py", line 140, in run
  File "dist\libopensesame\experiment.py", line 397, in run
  File "dist\libopensesame\item_store.py", line 95, in execute
  File "dist\libopensesame\item_store.py", line 110, in run
  File "dist\libopensesame\sequence.py", line 50, in run
  File "dist\libopensesame\item_store.py", line 110, in run
  File "C:\Program Files (x86)\OpenSesame\plugins\pygaze_init\pygaze_init.py", line 212, in run
  File "C:\Program Files (x86)\OpenSesame\pygaze\_eyetracker\libeyetribe.py", line 208, in calibrate
  File "C:\Program Files (x86)\OpenSesame\pygaze\_eyetracker\pytribe.py", line 1411, in pointend
KeyError: 'values'
```

We're using these versions:
- OpenSesame 3.0.7
- Python 2.7.10
- Windows 7 Enterprise, Service Pack 1
- EyeTribe SDK 0.9.77
- PyGaze 0.6.0a10, the most recent Git commit
